Workbook

Sheet generic_format
A1: generic placeholders (templates) for all IDs and codes in academic hierarchy so the format stays consistent across tables.
A2: 1. Faculty | C2: 2. Department
A3: Pattern | C3: Pattern
A4: FAC-[FAC_CODE] | C4: DEP-[FAC_CODE]-[DEPT_CODE]
A5: Example | B5: FAC-ENG | C5: Example | D5: DEP-ENG-CSE
B6: FAC-SCI | D6: DEP-SCI-PHY
B7: FAC-MGT | D7: DEP-MGT-BA
B8: FAC-LAW
A9: Field | B9: Placeholder | C9: Field | D9: Placeholder
A10: faculty_id | B10: FAC-[FAC] | C10: department_id | D10: DEP-[FAC]-[DEPT]
A11: faculty_code | B11: [FAC] | C11: department_code | D11: [DEPT]
A12: 3. Program | C12: 4. Specialization
A13: Pattern | C13: Pattern
A14: PRG-[FAC_CODE]-[DEPT_CODE]-[PROGRAM_CODE] | C14: SPC-[FAC_CODE]-[DEPT_CODE]-[PROGRAM_CODE]-[SPEC_CODE]
A15: Example | B15: PRG-ENG-CSE-BTECH-CSE | C15: Example | D15: SPC-ENG-CSE-BTECH-CSE-AI
B16: PRG-SCI-PHY-BSC-PHY | D16: SPC-ENG-ME-BTECH-ME-MECH
B17: PRG-MGT-BA-MBA | D17: SPC-MGT-BA-MBA-FIN
A18: Field | B18: Placeholder | C18: Field | D18: Placeholder
A19: program_id | B19: PRG-[FAC]-[DEPT]-[PROG] | C19: specialization_id | D19: SPC-[FAC]-[DEPT]-[PROG]-[SPEC]
A20: program_code | B20: [PROG] | C20: specialization_code | D20: [SPEC]
A21: 5. Course | C21: 6. Batch
A22: Pattern | C22: Pattern
A23: CRS-[FAC_CODE]-[DEPT_CODE]-[PROGRAM_CODE]-[COURSE_CODE] | C23: BA-[FAC_CODE]-[DEPT_CODE]-[PROGRAM_CODE]-[YEAR]
A24: Example | B24: CRS-ENG-CSE-BTECH-CSE-DSA | C24: Example | D24: BA-ENG-CSE-BTECH-CSE-2024
B25: CRS-ENG-CSE-BTECH-CSE-ML | D25: BA-MGT-BA-MBA-2025
A26: Field | B26: Placeholder | C26: Field | D26: Placeholder
A27: course_id | B27: CRS-[FAC]-[DEPT]-[PROGRAM]-[COURSE] | C27: batch_id | D27: BA-[FAC]-[DEPT]-[PROGRAM]-[YEAR]
A28: course_code | C28: batch_code | D28: [YEAR]
A29: 7. Section | C29: 8. Student
A30: Pattern | C30: Pattern
A31: SEC-[FAC_CODE]-[DEPT_CODE]-[PROGRAM_CODE]-[YEAR]-[SECTION] | C31: STU-[PROGRAM_CODE]-[YEAR]-[ROLL_NO]
A32: Example | B32: SEC-ENG-CSE-BTECH-CSE-2024-A | C32: Example | D32: STU-BTECH-CSE-2024-0001
B33: SEC-ENG-CSE-BTECH-CSE-2024-B | D33: STU-MBA-2025-0001
A34: Field | B34: Placeholder | C34: Field | D34: Placeholder
A35: section_id | B35: SEC-[FAC]-[DEPT]-[PROGRAM]-[YEAR]-[SECTION] | C35: student_id | D35: STU-[PROGRAM]-[YEAR]-[ROLL]
A36: section_code | B36: [SECTION] | C36: student_code | D36: [ROLL]
A37: 9. Teacher | C37: 10. Semester
A38: Pattern | C38: Pattern
A39: TCH-[DEPT_CODE]-[NUMBER] | C39: SEM-[PROGRAM_CODE]-[SEM_NO]
A40: Example | B40: TCH-CSE-001 | C40: Example | D40: SEM-BTECH-CSE-01
...

Sheet University_details
A1: university_id | B1: university_name
A2: UM | B2: UM UNIVERSITY

Sheet FACULTY_DATA
A1: university_id | B1: faculty_id | C1: faculty_code | D1: faculty_name
A2: UM | B2: FAC-AHS | C2: {=INDEX(_xlfn.TEXTSPLIT(B2,"-"),2)} -> AHS | D2: Faculty of Allied Health Sciences
A3: UM | B3: FAC-AHSS | C3: {=INDEX(_xlfn.TEXTSPLIT(B3,"-"),2)} -> AHSS | D3: Faculty of Arts, Humanities & Social Sciences
A4: UM | B4: FAC-COM | C4: {=INDEX(_xlfn.TEXTSPLIT(B4,"-"),2)} -> COM | D4: Faculty of Commerce
A5: UM | B5: FAC-ENG | C5: {=INDEX(_xlfn.TEXTSPLIT(B5,"-"),2)} -> ENG | D5: Faculty of Engineering
A6: UM | B6: FAC-LAW | C6: {=INDEX(_xlfn.TEXTSPLIT(B6,"-"),2)} -> LAW | D6: Faculty of Law
A7: UM | B7: FAC-MGT | C7: {=INDEX(_xlfn.TEXTSPLIT(B7,"-"),2)} -> MGT | D7: Faculty of Management
A8: UM | B8: FAC-PHR | C8: {=INDEX(_xlfn.TEXTSPLIT(B8,"-"),2)} -> PHR | D8: Faculty of Pharmacy
A9: UM | B9: FAC-SCI | C9: {=INDEX(_xlfn.TEXTSPLIT(B9,"-"),2)} -> SCI | D9: Faculty of Science

Sheet DEPARTMENT_DATA
A1: faculty_id | B1: faculty_code | C1: department_id | D1: department_code | E1: department_name
A2: FAC-AHS | B2: =_xlfn.XLOOKUP(A2,FACULTY_DATA!$B$2:$B$9,FACULTY_DATA!$C$2:$C$9) -> AHS | C2: ="DEP-"&B2&"-"&D2 -> DEP-AHS-HS | D2: HS | E2: Department of Health Sciences
A3: FAC-AHSS | B3: =_xlfn.XLOOKUP(A3,FACULTY_DATA!$B$2:$B$9,FACULTY_DATA!$C$2:$C$9) -> AHSS | C3: ="DEP-"&B3&"-"&D3 -> DEP-AHSS-JMC | D3: JMC | E3: Department of Journalism & Mass Communication
A4: FAC-AHSS | B4: =_xlfn.XLOOKUP(A4,FACULTY_DATA!$B$2:$B$9,FACULTY_DATA!$C$2:$C$9) -> AHSS | C4: ="DEP-"&B4&"-"&D4 -> DEP-AHSS-ENG | D4: ENG | E4: Department of English
A5: FAC-COM | B5: =_xlfn.XLOOKUP(A5,FACULTY_DATA!$B$2:$B$9,FACULTY_DATA!$C$2:$C$9) -> COM | C5: ="DEP-"&B5&"-"&D5 -> DEP-COM-COM | D5: COM | E5: Department of Commerce
A6: FAC-ENG | B6: =_xlfn.XLOOKUP(A6,FACULTY_DATA!$B$2:$B$9,FACULTY_DATA!$C$2:$C$9) -> ENG | C6: ="DEP-"&B6&"-"&D6 -> DEP-ENG-CSE | D6: CSE | E6: Department of Computer Science Engineering
A7: FAC-ENG | B7: =_xlfn.XLOOKUP(A7,FACULTY_DATA!$B$2:$B$9,FACULTY_DATA!$C$2:$C$9) -> ENG | C7: ="DEP-"&B7&"-"&D7 -> DEP-ENG-IT | D7: IT | E7: Department of Information Technology
A8: FAC-ENG | B8: =_xlfn.XLOOKUP(A8,FACULTY_DATA!$B$2:$B$9,FACULTY_DATA!$C$2:$C$9) -> ENG | C8: ="DEP-"&B8&"-"&D8 -> DEP-ENG-RA | D8: RA | E8: Department of Robotics & Automation
A9: FAC-ENG | B9: =_xlfn.XLOOKUP(A9,FACULTY_DATA!$B$2:$B$9,FACULTY_DATA!$C$2:$C$9) -> ENG | C9: ="DEP-"&B9&"-"&D9 -> DEP-ENG-AE | D9: AE | E9: Department of Automobile Engineering
A10: FAC-ENG | B10: =_xlfn.XLOOKUP(A10,FACULTY_DATA!$B$2:$B$9,FACULTY_DATA!$C$2:$C$9) -> ENG | C10: ="DEP-"&B10&"-"&D10 -> DEP-ENG-CE | D10: CE | E10: Department of Civil Engineering
A11: FAC-ENG | B11: =_xlfn.XLOOKUP(A11,FACULTY_DATA!$B$2:$B$9,FACULTY_DATA!$C$2:$C$9) -> ENG | C11: ="DEP-"&B11&"-"&D11 -> DEP-ENG-ECE | D11: ECE | E11: Department of Electronics & Communication Engineering
A12: FAC-ENG | B12: =_xlfn.XLOOKUP(A12,FACULTY_DATA!$B$2:$B$9,FACULTY_DATA!$C$2:$C$9) -> ENG | C12: ="DEP-"&B12&"-"&D12 -> DEP-ENG-EE | D12: EE | E12: Department of Electrical Engineering
A13: FAC-ENG | B13: =_xlfn.XLOOKUP(A13,FACULTY_DATA!$B$2:$B$9,FACULTY_DATA!$C$2:$C$9) -> ENG | C13: ="DEP-"&B13&"-"&D13 -> DEP-ENG-ME | D13: ME | E13: Department of Mechanical Engineering
... A24: FAC-SCI | B24: =_xlfn.XLOOKUP(A24,FACULTY_DATA!$B$2:$B$9,FACULTY_DATA!$C$2:$C$9) -> SCI | C24: ="DEP-"&B24&"-"&D24 -> DEP-SCI-MATH | D24: MATH | E24: Department of Mathematics

Sheet PROGRAM_DATA
A1: Department_id | B1: Department_name | C1: Program_id | D1: Program_code | E1: Program_Name | F1: duration(years) | G1: total_semesters | H1: Degree Type
A2: =_xlfn.XLOOKUP(B2,DEPARTMENT_DATA!$E$2:$E$24,DEPARTMENT_DATA!$C$2:$C$24) -> DEP-AHS-HS | B2: Department of Health Sciences | C2: PRG-AHS-HS-BSC | D2: BSC | E2: Bachelor of Science | F2: {=_xlfn.IFS( ISNUMBER(SEARCH("Integrated",E2)), "5", ISNUMBER(SEARCH("Bachelor of Technology",E2)), "4", ISNUMBER(SEARCH("Bachelor of Pharmacy",E2)), "4", ISNUMBER(SEARCH("Bachelor of Science in Agriculture",E2)), "4", ISNUMBER(SEARCH("Bachelor of Arts and Bachelor of Laws",E2)), "5", ISNUMBER(SEARCH("Bachelor of Business Administration and Bachelor of Laws",E2)), "5", ISNUMBER(SEARCH("Master of Laws",E2)), "1", ISNUMBER(SEARCH("Master",E2)), "2", ISNUMBER(SEARCH("Bachelor",E2)), "3" )} -> 3 | G2: =2*F2 -> 6 | H2: Degree
A3: =_xlfn.XLOOKUP(B3,DEPARTMENT_DATA!$E$2:$E$24,DEPARTMENT_DATA!$C$2:$C$24) -> DEP-AHSS-JMC | B3: Department of Journalism & Mass Communication | C3: PRG-AHSS-JMC-BJMC | D3: BJMC | E3: Bachelor of Journalism and Mass Communication | F3: {=_xlfn.IFS( ISNUMBER(SEARCH("Integrated",E3)), "5", ISNUMBER(SEARCH("Bachelor of Technology",E3)), "4", ISNUMBER(SEARCH("Bachelor of Pharmacy",E3)), "4", ISNUMBER(SEARCH("Bachelor of Science in Agriculture",E3)), "4", ISNUMBER(SEARCH("Bachelor of Arts and Bachelor of Laws",E3)), "5", ISNUMBER(SEARCH("Bachelor of Business Administration and Bachelor of Laws",E3)), "5", ISNUMBER(SEARCH("Master of Laws",E3)), "1", ISNUMBER(SEARCH("Master",E3)), "2", ISNUMBER(SEARCH("Bachelor",E3)), "3" )} -> 3 | G3: =2*F3 -> 6 | H3: Degree
A4: =_xlfn.XLOOKUP(B4,DEPARTMENT_DATA!$E$2:$E$24,DEPARTMENT_DATA!$C$2:$C$24) -> DEP-AHSS-ENG | B4: Department of English | C4: PRG-AHSS-ENG-MA-ENG | D4: MA-ENG | E4: Master of Arts in English | F4: {=_xlfn.IFS( ISNUMBER(SEARCH("Integrated",E4)), "5", ISNUMBER(SEARCH("Bachelor of Technology",E4)), "4", ISNUMBER(SEARCH("Bachelor of Pharmacy",E4)), "4", ISNUMBER(SEARCH("Bachelor of Science in Agriculture",E4)), "4", ISNUMBER(SEARCH("Bachelor of Arts and Bachelor of Laws",E4)), "5", ISNUMBER(SEARCH("Bachelor of Business Administration and Bachelor of Laws",E4)), "5", ISNUMBER(SEARCH("Master of Laws",E4)), "1", ISNUMBER(SEARCH("Master",E4)), "2", ISNUMBER(SEARCH("Bachelor",E4)), "3" )} -> 2 | G4: =2*F4 -> 4 | H4: Degree
A5: =_xlfn.XLOOKUP(B5,DEPARTMENT_DATA!$E$2:$E$24,DEPARTMENT_DATA!$C$2:$C$24) -> DEP-COM-COM | B5: Department of Commerce | C5: PRG-COM-COM-BCOM | D5: BCOM | E5: Bachelor of Commerce | F5: {=_xlfn.IFS( ISNUMBER(SEARCH("Integrated",E5)), "5", ISNUMBER(SEARCH("Bachelor of Technology",E5)), "4", ISNUMBER(SEARCH("Bachelor of Pharmacy",E5)), "4", ISNUMBER(SEARCH("Bachelor of Science in Agriculture",E5)), "4", ISNUMBER(SEARCH("Bachelor of Arts and Bachelor of Laws",E5)), "5", ISNUMBER(SEARCH("Bachelor of Business Administration and Bachelor of Laws",E5)), "5", ISNUMBER(SEARCH("Master of Laws",E5)), "1", ISNUMBER(SEARCH("Master",E5)), "2", ISNUMBER(SEARCH("Bachelor",E5)), "3" )} -> 3 | G5: =2*F5 -> 6 | H5: Degree
A6: =_xlfn.XLOOKUP(B6,DEPARTMENT_DATA!$E$2:$E$24,DEPARTMENT_DATA!$C$2:$C$24) -> DEP-COM-COM | B6: Department of Commerce | C6: PRG-COM-COM-BCOM-GF | D6: BCOM-GF | E6: Bachelor of Commerce in Global Finance | F6: {=_xlfn.IFS( ISNUMBER(SEARCH("Integrated",E6)), "5", ISNUMBER(SEARCH("Bachelor of Technology",E6)), "4", ISNUMBER(SEARCH("Bachelor of Pharmacy",E6)), "4", ISNUMBER(SEARCH("Bachelor of Science in Agriculture",E6)), "4", ISNUMBER(SEARCH("Bachelor of Arts and Bachelor of Laws",E6)), "5", ISNUMBER(SEARCH("Bachelor of Business Administration and Bachelor of Laws",E6)), "5", ISNUMBER(SEARCH("Master of Laws",E6)), "1", ISNUMBER(SEARCH("Master",E6)), "2", ISNUMBER(SEARCH("Bachelor",E6)), "3" )} -> 3 | G6: =2*F6 -> 6 | H6: Degree
A7: =_xlfn.XLOOKUP(B7,DEPARTMENT_DATA!$E$2:$E$24,DEPARTMENT_DATA!$C$2:$C$24) -> DEP-ENG-CSE | B7: Department of Computer Science Engineering | C7: PRG-ENG-CSE-BTECH-CSE | D7: BTECH-CSE | E7: Bachelor of Technology in Computer Science Engineering | F7: {=_xlfn.IFS( ISNUMBER(SEARCH("Integrated",E7)), "5", ISNUMBER(SEARCH("Bachelor of Technology",E7)), "4", ISNUMBER(SEARCH("Bachelor of Pharmacy",E7)), "4", ISNUMBER(SEARCH("Bachelor of Science in Agriculture",E7)), "4", ISNUMBER(SEARCH("Bachelor of Arts and Bachelor of Laws",E7)), "5", ISNUMBER(SEARCH("Bachelor of Business Administration and Bachelor of Laws",E7)), "5", ISNUMBER(SEARCH("Master of Laws",E7)), "1", ISNUMBER(SEARCH("Master",E7)), "2", ISNUMBER(SEARCH("Bachelor",E7)), "3" )} -> 4 | G7: =2*F7 -> 8 | H7: Degree
A8: =_xlfn.XLOOKUP(B8,DEPARTMENT_DATA!$E$2:$E$24,DEPARTMENT_DATA!$C$2:$C$24) -> DEP-ENG-CSE | B8: Department of Computer Science Engineering | C8: PRG-ENG-CSE-INT-CSE | D8: INT-CSE | E8: Integrated Bachelor and Master of Technology in Computer Science Engineering | F8: {=_xlfn.IFS( ISNUMBER(SEARCH("Integrated",E8)), "5", ISNUMBER(SEARCH("Bachelor of Technology",E8)), "4", ISNUMBER(SEARCH("Bachelor of Pharmacy",E8)), "4", ISNUMBER(SEARCH("Bachelor of Science in Agriculture",E8)), "4", ISNUMBER(SEARCH("Bachelor of Arts and Bachelor of Laws",E8)), "5", ISNUMBER(SEARCH("Bachelor of Business Administration and Bachelor of Laws",E8)), "5", ISNUMBER(SEARCH("Master of Laws",E8)), "1", ISNUMBER(SEARCH("Master",E8)), "2", ISNUMBER(SEARCH("Bachelor",E8)), "3" )} -> 5 | G8: =2*F8 -> 10 | H8: Degree
A9: =_xlfn.XLOOKUP(B9,DEPARTMENT_DATA!$E$2:$E$24,DEPARTMENT_DATA!$C$2:$C$24) -> DEP-ENG-CSE | B9: Department of Computer Science Engineering | C9: PRG-ENG-CSE-MTECH-CSE | D9: MTECH-CSE | E9: Master of Technology in Computer Science Engineering | F9: {=_xlfn.IFS( ISNUMBER(SEARCH("Integrated",E9)), "5", ISNUMBER(SEARCH("Bachelor of Technology",E9)), "4", ISNUMBER(SEARCH("Bachelor of Pharmacy",E9)), "4", ISNUMBER(SEARCH("Bachelor of Science in Agriculture",E9)), "4", ISNUMBER(SEARCH("Bachelor of Arts and Bachelor of Laws",E9)), "5", ISNUMBER(SEARCH("Bachelor of Business Administration and Bachelor of Laws",E9)), "5", ISNUMBER(SEARCH("Master of Laws",E9)), "1", ISNUMBER(SEARCH("Master",E9)), "2", ISNUMBER(SEARCH("Bachelor",E9)), "3" )} -> 2 | G9: =2*F9 -> 4 | H9: Degree
A10: =_xlfn.XLOOKUP(B10,DEPARTMENT_DATA!$E$2:$E$24,DEPARTMENT_DATA!$C$2:$C$24) -> DEP-ENG-CSE | B10: Department of Computer Science Engineering | C10: PRG-ENG-CSE-BCA | D10: BCA | E10: Bachelor of Computer Applications | F10: {=_xlfn.IFS( ISNUMBER(SEARCH("Integrated",E10)), "5", ISNUMBER(SEARCH("Bachelor of Technology",E10)), "4", ISNUMBER(SEARCH("Bachelor of Pharmacy",E10)), "4", ISNUMBER(SEARCH("Bachelor of Science in Agriculture",E10)), "4", ISNUMBER(SEARCH("Bachelor of Arts and Bachelor of Laws",E10)), "5", ISNUMBER(SEARCH("Bachelor of Business Administration and Bachelor of Laws",E10)), "5", ISNUMBER(SEARCH("Master of Laws",E10)), "1", ISNUMBER(SEARCH("Master",E10)), "2", ISNUMBER(SEARCH("Bachelor",E10)), "3" )} -> 3 | G10: =2*F10 -> 6 | H10: Degree
A11: =_xlfn.XLOOKUP(B11,DEPARTMENT_DATA!$E$2:$E$24,DEPARTMENT_DATA!$C$2:$C$24) -> DEP-ENG-CSE | B11: Department of Computer Science Engineering | C11: PRG-ENG-CSE-MCA | D11: MCA | E11: Master of Computer Applications | F11: {=_xlfn.IFS( ISNUMBER(SEARCH("Integrated",E11)), "5", ISNUMBER(SEARCH("Bachelor of Technology",E11)), "4", ISNUMBER(SEARCH("Bachelor of Pharmacy",E11)), "4", ISNUMBER(SEARCH("Bachelor of Science in Agriculture",E11)), "4", ISNUMBER(SEARCH("Bachelor of Arts and Bachelor of Laws",E11)), "5", ISNUMBER(SEARCH("Bachelor of Business Administration and Bachelor of Laws",E11)), "5", ISNUMBER(SEARCH("Master of Laws",E11)), "1", ISNUMBER(SEARCH("Master",E11)), "2", ISNUMBER(SEARCH("Bachelor",E11)), "3" )} -> 2 | G11: =2*F11 -> 4 | H11: Degree
A12: =_xlfn.XLOOKUP(B12,DEPARTMENT_DATA!$E$2:$E$24,DEPARTMENT_DATA!$C$2:$C$24) -> DEP-ENG-IT | B12: Department of Information Technology | C12: PRG-ENG-IT-BTECH-IT | D12: BTECH-IT | E12: Bachelor of Technology in Information Technology | F12: {=_xlfn.IFS( ISNUMBER(SEARCH("Integrated",E12)), "5", ISNUMBER(SEARCH("Bachelor of Technology",E12)), "4", ISNUMBER(SEARCH("Bachelor of Pharmacy",E12)), "4", ISNUMBER(SEARCH("Bachelor of Science in Agriculture",E12)), "4", ISNUMBER(SEARCH("Bachelor of Arts and Bachelor of Laws",E12)), "5", ISNUMBER(SEARCH("Bachelor of Business Administration and Bachelor of Laws",E12)), "5", ISNUMBER(SEARCH("Master of Laws",E12)), "1", ISNUMBER(SEARCH("Master",E12)), "2", ISNUMBER(SEARCH("Bachelor",E12)), "3" )} -> 4 | G12: =2*F12 -> 8 | H12: Degree
A13: =_xlfn.XLOOKUP(B13,DEPARTMENT_DATA!$E$2:$E$24,DEPARTMENT_DATA!$C$2:$C$24) -> DEP-ENG-IT | B13: Department of Information Technology | C13: PRG-ENG-IT-MTECH-IT | D13: MTECH-IT | E13: Master of Technology in Information Technology | F13: {=_xlfn.IFS( ISNUMBER(SEARCH("Integrated",E13)), "5", ISNUMBER(SEARCH("Bachelor of Technology",E13)), "4", ISNUMBER(SEARCH("Bachelor of Pharmacy",E13)), "4", ISNUMBER(SEARCH("Bachelor of Science in Agriculture",E13)), "4", ISNUMBER(SEARCH("Bachelor of Arts and Bachelor of Laws",E13)), "5", ISNUMBER(SEARCH("Bachelor of Business Administration and Bachelor of Laws",E13)), "5", ISNUMBER(SEARCH("Master of Laws",E13)), "1", ISNUMBER(SEARCH("Master",E13)), "2", ISNUMBER(SEARCH("Bachelor",E13)), "3" )} -> 2 | G13: =2*F13 -> 4 | H13: Degree
... A45: =_xlfn.XLOOKUP(B45,DEPARTMENT_DATA!$E$2:$E$24,DEPARTMENT_DATA!$C$2:$C$24) -> DEP-SCI-MATH | B45: Department of Mathematics | C45: PRG-SCI-MATH-MSC-MATH | D45: MSC-MATH | E45: Master of Science in Mathematics | F45: {=_xlfn.IFS( ISNUMBER(SEARCH("Integrated",E45)), "5", ISNUMBER(SEARCH("Bachelor of Technology",E45)), "4", ISNUMBER(SEARCH("Bachelor of Pharmacy",E45)), "4", ISNUMBER(SEARCH("Bachelor of Science in Agriculture",E45)), "4", ISNUMBER(SEARCH("Bachelor of Arts and Bachelor of Laws",E45)), "5", ISNUMBER(SEARCH("Bachelor of Business Administration and Bachelor of Laws",E45)), "5", ISNUMBER(SEARCH("Master of Laws",E45)), "1", ISNUMBER(SEARCH("Master",E45)), "2", ISNUMBER(SEARCH("Bachelor",E45)), "3" )} -> 2 | G45: =2*F45 -> 4 | H45: Degree

Sheet SPECIALIZATION_DATA
A1: Faculty_id | B1: Faculty_code | C1: Department_id | D1: Department_code | E1: Department | F1: Program_code | G1: Program_name | H1: Specialization_id | I1: Specialization_code | J1: Specialization
A2: =_xlfn.XLOOKUP(C2,DEPARTMENT_DATA!$C$2:$C$24,DEPARTMENT_DATA!$A$2:$A$24) -> FAC-ENG | B2: =_xlfn.XLOOKUP(A2,DEPARTMENT_DATA!$A$2:$A$24,DEPARTMENT_DATA!$B$2:$B$24) -> ENG | C2: =_xlfn.XLOOKUP(E2,DEPARTMENT_DATA!$E$2:$E$24,DEPARTMENT_DATA!$C$2:$C$24) -> DEP-ENG-CSE | D2: =_xlfn.XLOOKUP(E2,DEPARTMENT_DATA!$E$2:$E$24,DEPARTMENT_DATA!$D$2:$D$24) -> CSE | E2: Department of Computer Science Engineering | F2: =_xlfn.XLOOKUP(G2,PROGRAM_DATA!$E$2:$E$45,PROGRAM_DATA!$D$2:$D$45) -> BTECH-CSE | G2: Bachelor of Technology in Computer Science Engineering | H2: ="SPC-"&B2&"-"&D2&"-"&F2&"-"&I2 -> SPC-ENG-CSE-BTECH-CSE-AI | I2: AI | J2: Artificial Intelligence
A3: =_xlfn.XLOOKUP(C3,DEPARTMENT_DATA!$C$2:$C$24,DEPARTMENT_DATA!$A$2:$A$24) -> FAC-ENG | B3: =_xlfn.XLOOKUP(A3,DEPARTMENT_DATA!$A$2:$A$24,DEPARTMENT_DATA!$B$2:$B$24) -> ENG | C3: =_xlfn.XLOOKUP(E3,DEPARTMENT_DATA!$E$2:$E$24,DEPARTMENT_DATA!$C$2:$C$24) -> DEP-ENG-CSE | D3: =_xlfn.XLOOKUP(E3,DEPARTMENT_DATA!$E$2:$E$24,DEPARTMENT_DATA!$D$2:$D$24) -> CSE | E3: Department of Computer Science Engineering | F3: =_xlfn.XLOOKUP(G3,PROGRAM_DATA!$E$2:$E$45,PROGRAM_DATA!$D$2:$D$45) -> BTECH-CSE | G3: Bachelor of Technology in Computer Science Engineering | H3: ="SPC-"&B3&"-"&D3&"-"&F3&"-"&I3 -> SPC-ENG-CSE-BTECH-CSE-DS | I3: DS | J3: Data Science
A4: =_xlfn.XLOOKUP(C4,DEPARTMENT_DATA!$C$2:$C$24,DEPARTMENT_DATA!$A$2:$A$24) -> FAC-ENG | B4: =_xlfn.XLOOKUP(A4,DEPARTMENT_DATA!$A$2:$A$24,DEPARTMENT_DATA!$B$2:$B$24) -> ENG | C4: =_xlfn.XLOOKUP(E4,DEPARTMENT_DATA!$E$2:$E$24,DEPARTMENT_DATA!$C$2:$C$24) -> DEP-ENG-CSE | D4: =_xlfn.XLOOKUP(E4,DEPARTMENT_DATA!$E$2:$E$24,DEPARTMENT_DATA!$D$2:$D$24) -> CSE | E4: Department of Computer Science Engineering | F4: =_xlfn.XLOOKUP(G4,PROGRAM_DATA!$E$2:$E$45,PROGRAM_DATA!$D$2:$D$45) -> BTECH-CSE | G4: Bachelor of Technology in Computer Science Engineering | H4: ="SPC-"&B4&"-"&D4&"-"&F4&"-"&I4 -> SPC-ENG-CSE-BTECH-CSE-CSBS | I4: CSBS | J4: Computer Science & Business Systems
A5: =_xlfn.XLOOKUP(C5,DEPARTMENT_DATA!$C$2:$C$24,DEPARTMENT_DATA!$A$2:$A$24) -> FAC-ENG | B5: =_xlfn.XLOOKUP(A5,DEPARTMENT_DATA!$A$2:$A$24,DEPARTMENT_DATA!$B$2:$B$24) -> ENG | C5: =_xlfn.XLOOKUP(E5,DEPARTMENT_DATA!$E$2:$E$24,DEPARTMENT_DATA!$C$2:$C$24) -> DEP-ENG-AE | D5: =_xlfn.XLOOKUP(E5,DEPARTMENT_DATA!$E$2:$E$24,DEPARTMENT_DATA!$D$2:$D$24) -> AE | E5: Department of Automobile Engineering | F5: =_xlfn.XLOOKUP(G5,PROGRAM_DATA!$E$2:$E$45,PROGRAM_DATA!$D$2:$D$45) -> BTECH-AE | G5: Bachelor of Technology in Automobile Engineering | H5: ="SPC-"&B5&"-"&D5&"-"&F5&"-"&I5 -> SPC-ENG-AE-BTECH-AE-EV | I5: EV | J5: Electric Vehicle
A6: =_xlfn.XLOOKUP(C6,DEPARTMENT_DATA!$C$2:$C$24,DEPARTMENT_DATA!$A$2:$A$24) -> FAC-ENG | B6: =_xlfn.XLOOKUP(A6,DEPARTMENT_DATA!$A$2:$A$24,DEPARTMENT_DATA!$B$2:$B$24) -> ENG | C6: =_xlfn.XLOOKUP(E6,DEPARTMENT_DATA!$E$2:$E$24,DEPARTMENT_DATA!$C$2:$C$24) -> DEP-ENG-CE | D6: =_xlfn.XLOOKUP(E6,DEPARTMENT_DATA!$E$2:$E$24,DEPARTMENT_DATA!$D$2:$D$24) -> CE | E6: Department of Civil Engineering | F6: =_xlfn.XLOOKUP(G6,PROGRAM_DATA!$E$2:$E$45,PROGRAM_DATA!$D$2:$D$45) -> BTECH-CE | G6: Bachelor of Technology in Civil Engineering | H6: ="SPC-"&B6&"-"&D6&"-"&F6&"-"&I6 -> SPC-ENG-CE-BTECH-CE-CTM | I6: CTM | J6: Construction Technology & Management
A7: =_xlfn.XLOOKUP(C7,DEPARTMENT_DATA!$C$2:$C$24,DEPARTMENT_DATA!$A$2:$A$24) -> FAC-ENG | B7: =_xlfn.XLOOKUP(A7,DEPARTMENT_DATA!$A$2:$A$24,DEPARTMENT_DATA!$B$2:$B$24) -> ENG | C7: =_xlfn.XLOOKUP(E7,DEPARTMENT_DATA!$E$2:$E$24,DEPARTMENT_DATA!$C$2:$C$24) -> DEP-ENG-CE | D7: =_xlfn.XLOOKUP(E7,DEPARTMENT_DATA!$E$2:$E$24,DEPARTMENT_DATA!$D$2:$D$24) -> CE | E7: Department of Civil Engineering | F7: =_xlfn.XLOOKUP(G7,PROGRAM_DATA!$E$2:$E$45,PROGRAM_DATA!$D$2:$D$45) -> BTECH-CE | G7: Bachelor of Technology in Civil Engineering | H7: ="SPC-"&B7&"-"&D7&"-"&F7&"-"&I7 -> SPC-ENG-CE-BTECH-CE-SE | I7: SE | J7: Structural Engineering
A8: =_xlfn.XLOOKUP(C8,DEPARTMENT_DATA!$C$2:$C$24,DEPARTMENT_DATA!$A$2:$A$24) -> FAC-ENG | B8: =_xlfn.XLOOKUP(A8,DEPARTMENT_DATA!$A$2:$A$24,DEPARTMENT_DATA!$B$2:$B$24) -> ENG | C8: =_xlfn.XLOOKUP(E8,DEPARTMENT_DATA!$E$2:$E$24,DEPARTMENT_DATA!$C$2:$C$24) -> DEP-ENG-CE | D8: =_xlfn.XLOOKUP(E8,DEPARTMENT_DATA!$E$2:$E$24,DEPARTMENT_DATA!$D$2:$D$24) -> CE | E8: Department of Civil Engineering | F8: =_xlfn.XLOOKUP(G8,PROGRAM_DATA!$E$2:$E$45,PROGRAM_DATA!$D$2:$D$45) -> BTECH-CE | G8: Bachelor of Technology in Civil Engineering | H8: ="SPC-"&B8&"-"&D8&"-"&F8&"-"&I8 -> SPC-ENG-CE-BTECH-CE-EE | I8: EE | J8: Environmental Engineering
A9: =_xlfn.XLOOKUP(C9,DEPARTMENT_DATA!$C$2:$C$24,DEPARTMENT_DATA!$A$2:$A$24) -> FAC-ENG | B9: =_xlfn.XLOOKUP(A9,DEPARTMENT_DATA!$A$2:$A$24,DEPARTMENT_DATA!$B$2:$B$24) -> ENG | C9: =_xlfn.XLOOKUP(E9,DEPARTMENT_DATA!$E$2:$E$24,DEPARTMENT_DATA!$C$2:$C$24) -> DEP-ENG-CE | D9: =_xlfn.XLOOKUP(E9,DEPARTMENT_DATA!$E$2:$E$24,DEPARTMENT_DATA!$D$2:$D$24) -> CE | E9: Department of Civil Engineering | F9: =_xlfn.XLOOKUP(G9,PROGRAM_DATA!$E$2:$E$45,PROGRAM_DATA!$D$2:$D$45) -> BTECH-CE | G9: Bachelor of Technology in Civil Engineering | H9: ="SPC-"&B9&"-"&D9&"-"&F9&"-"&I9 -> SPC-ENG-CE-BTECH-CE-AI | I9: AI | J9: Artificial Intelligence
A10: =_xlfn.XLOOKUP(C10,DEPARTMENT_DATA!$C$2:$C$24,DEPARTMENT_DATA!$A$2:$A$24) -> FAC-ENG | B10: =_xlfn.XLOOKUP(A10,DEPARTMENT_DATA!$A$2:$A$24,DEPARTMENT_DATA!$B$2:$B$24) -> ENG | C10: =_xlfn.XLOOKUP(E10,DEPARTMENT_DATA!$E$2:$E$24,DEPARTMENT_DATA!$C$2:$C$24) -> DEP-ENG-ECE | D10: =_xlfn.XLOOKUP(E10,DEPARTMENT_DATA!$E$2:$E$24,DEPARTMENT_DATA!$D$2:$D$24) -> ECE | E10: Department of Electronics & Communication Engineering | F10: =_xlfn.XLOOKUP(G10,PROGRAM_DATA!$E$2:$E$45,PROGRAM_DATA!$D$2:$D$45) -> BTECH-ECE | G10: Bachelor of Technology in Electronics and Communication Engineering | H10: ="SPC-"&B10&"-"&D10&"-"&F10&"-"&I10 -> SPC-ENG-ECE-BTECH-ECE-CE | I10: CE | J10: Communication Engineering
A11: =_xlfn.XLOOKUP(C11,DEPARTMENT_DATA!$C$2:$C$24,DEPARTMENT_DATA!$A$2:$A$24) -> FAC-ENG | B11: =_xlfn.XLOOKUP(A11,DEPARTMENT_DATA!$A$2:$A$24,DEPARTMENT_DATA!$B$2:$B$24) -> ENG | C11: =_xlfn.XLOOKUP(E11,DEPARTMENT_DATA!$E$2:$E$24,DEPARTMENT_DATA!$C$2:$C$24) -> DEP-ENG-ECE | D11: =_xlfn.XLOOKUP(E11,DEPARTMENT_DATA!$E$2:$E$24,DEPARTMENT_DATA!$D$2:$D$24) -> ECE | E11: Department of Electronics & Communication Engineering | F11: =_xlfn.XLOOKUP(G11,PROGRAM_DATA!$E$2:$E$45,PROGRAM_DATA!$D$2:$D$45) -> BTECH-ECE | G11: Bachelor of Technology in Electronics and Communication Engineering | H11: ="SPC-"&B11&"-"&D11&"-"&F11&"-"&I11 -> SPC-ENG-ECE-BTECH-ECE-CT | I11: CT | J11: Computer Technology
A12: =_xlfn.XLOOKUP(C12,DEPARTMENT_DATA!$C$2:$C$24,DEPARTMENT_DATA!$A$2:$A$24) -> FAC-ENG | B12: =_xlfn.XLOOKUP(A12,DEPARTMENT_DATA!$A$2:$A$24,DEPARTMENT_DATA!$B$2:$B$24) -> ENG | C12: =_xlfn.XLOOKUP(E12,DEPARTMENT_DATA!$E$2:$E$24,DEPARTMENT_DATA!$C$2:$C$24) -> DEP-ENG-ECE | D12: =_xlfn.XLOOKUP(E12,DEPARTMENT_DATA!$E$2:$E$24,DEPARTMENT_DATA!$D$2:$D$24) -> ECE | E12: Department of Electronics & Communication Engineering | F12: =_xlfn.XLOOKUP(G12,PROGRAM_DATA!$E$2:$E$45,PROGRAM_DATA!$D$2:$D$45) -> BTECH-ECE | G12: Bachelor of Technology in Electronics and Communication Engineering | H12: ="SPC-"&B12&"-"&D12&"-"&F12&"-"&I12 -> SPC-ENG-ECE-BTECH-ECE-ME | I12: ME | J12: Microwave Engineering
A13: =_xlfn.XLOOKUP(C13,DEPARTMENT_DATA!$C$2:$C$24,DEPARTMENT_DATA!$A$2:$A$24) -> FAC-ENG | B13: =_xlfn.XLOOKUP(A13,DEPARTMENT_DATA!$A$2:$A$24,DEPARTMENT_DATA!$B$2:$B$24) -> ENG | C13: =_xlfn.XLOOKUP(E13,DEPARTMENT_DATA!$E$2:$E$24,DEPARTMENT_DATA!$C$2:$C$24) -> DEP-ENG-ECE | D13: =_xlfn.XLOOKUP(E13,DEPARTMENT_DATA!$E$2:$E$24,DEPARTMENT_DATA!$D$2:$D$24) -> ECE | E13: Department of Electronics & Communication Engineering | F13: =_xlfn.XLOOKUP(G13,PROGRAM_DATA!$E$2:$E$45,PROGRAM_DATA!$D$2:$D$45) -> BTECH-ECE | G13: Bachelor of Technology in Electronics and Communication Engineering | H13: ="SPC-"&B13&"-"&D13&"-"&F13&"-"&I13 -> SPC-ENG-ECE-BTECH-ECE-VLSI | I13: VLSI | J13: VLSI
... A36: =_xlfn.XLOOKUP(C36,DEPARTMENT_DATA!$C$2:$C$24,DEPARTMENT_DATA!$A$2:$A$24) -> FAC-AHS | B36: =_xlfn.XLOOKUP(A36,DEPARTMENT_DATA!$A$2:$A$24,DEPARTMENT_DATA!$B$2:$B$24) -> AHS | C36: =_xlfn.XLOOKUP(E36,DEPARTMENT_DATA!$E$2:$E$24,DEPARTMENT_DATA!$C$2:$C$24) -> DEP-AHS-HS | D36: =_xlfn.XLOOKUP(E36,DEPARTMENT_DATA!$E$2:$E$24,DEPARTMENT_DATA!$D$2:$D$24) -> HS | E36: Department of Health Sciences | F36: =_xlfn.XLOOKUP(G36,PROGRAM_DATA!$E$2:$E$45,PROGRAM_DATA!$D$2:$D$45) -> BSC | G36: Bachelor of Science | H36: ="SPC-"&B36&"-"&D36&"-"&F36&"-"&I36 -> SPC-AHS-HS-BSC-RT | I36: RT | J36: Respiratory Technology

Sheet rough_sheet
A1: faculty_id | B1: faculty_code | C1: faculty_name | D1: Department_id | E1: Department_code | F1: Department_name | G1: Program_id | H1: Program_code | I1: Program_Name
A2: =_xlfn.XLOOKUP(D2,DEPARTMENT_DATA!C$2:C$24,DEPARTMENT_DATA!A$2:A$24) -> FAC-AHS | B2: =_xlfn.XLOOKUP(E2,DEPARTMENT_DATA!D$2:D$24,DEPARTMENT_DATA!B$2:B$24) -> AHS | C2: =_xlfn.XLOOKUP(A2,FACULTY_DATA!$B$2:$B$9,FACULTY_DATA!$D$2:$D$9) -> Faculty of Allied Health Sciences | D2: DEP-AHS-HS | E2: =_xlfn.XLOOKUP(D2,DEPARTMENT_DATA!$C$2:$C$24,DEPARTMENT_DATA!$D$2:$D$24) -> HS | F2: Department of Health Sciences | G2: ="PRG-"&B2&"-"&E2&"-"&H2 -> PRG-AHS-HS-BSC | H2: BSC | I2: Bachelor of Science
A3: =_xlfn.XLOOKUP(D3,DEPARTMENT_DATA!C$2:C$24,DEPARTMENT_DATA!A$2:A$24) -> FAC-AHSS | B3: =_xlfn.XLOOKUP(E3,DEPARTMENT_DATA!D$2:D$24,DEPARTMENT_DATA!B$2:B$24) -> AHSS | C3: =_xlfn.XLOOKUP(A3,FACULTY_DATA!$B$2:$B$9,FACULTY_DATA!$D$2:$D$9) -> Faculty of Arts, Humanities & Social Sciences | D3: DEP-AHSS-JMC | E3: =_xlfn.XLOOKUP(D3,DEPARTMENT_DATA!$C$2:$C$24,DEPARTMENT_DATA!$D$2:$D$24) -> JMC | F3: Department of Journalism & Mass Communication | G3: ="PRG-"&B3&"-"&E3&"-"&H3 -> PRG-AHSS-JMC-BJMC | H3: BJMC | I3: Bachelor of Journalism and Mass Communication
A4: =_xlfn.XLOOKUP(D4,DEPARTMENT_DATA!C$2:C$24,DEPARTMENT_DATA!A$2:A$24) -> FAC-AHSS | B4: =_xlfn.XLOOKUP(E4,DEPARTMENT_DATA!D$2:D$24,DEPARTMENT_DATA!B$2:B$24) -> AHSS | C4: =_xlfn.XLOOKUP(A4,FACULTY_DATA!$B$2:$B$9,FACULTY_DATA!$D$2:$D$9) -> Faculty of Arts, Humanities & Social Sciences | D4: DEP-AHSS-ENG | E4: =_xlfn.XLOOKUP(D4,DEPARTMENT_DATA!$C$2:$C$24,DEPARTMENT_DATA!$D$2:$D$24) -> ENG | F4: Department of English | G4: ="PRG-"&B4&"-"&E4&"-"&H4 -> PRG-AHSS-ENG-MA-ENG | H4: MA-ENG | I4: Master of Arts in English
A5: =_xlfn.XLOOKUP(D5,DEPARTMENT_DATA!C$2:C$24,DEPARTMENT_DATA!A$2:A$24) -> FAC-COM | B5: =_xlfn.XLOOKUP(E5,DEPARTMENT_DATA!D$2:D$24,DEPARTMENT_DATA!B$2:B$24) -> COM | C5: =_xlfn.XLOOKUP(A5,FACULTY_DATA!$B$2:$B$9,FACULTY_DATA!$D$2:$D$9) -> Faculty of Commerce | D5: DEP-COM-COM | E5: =_xlfn.XLOOKUP(D5,DEPARTMENT_DATA!$C$2:$C$24,DEPARTMENT_DATA!$D$2:$D$24) -> COM | F5: Department of Commerce | G5: ="PRG-"&B5&"-"&E5&"-"&H5 -> PRG-COM-COM-BCOM | H5: BCOM | I5: Bachelor of Commerce
A6: =_xlfn.XLOOKUP(D6,DEPARTMENT_DATA!C$2:C$24,DEPARTMENT_DATA!A$2:A$24) -> FAC-COM | B6: =_xlfn.XLOOKUP(E6,DEPARTMENT_DATA!D$2:D$24,DEPARTMENT_DATA!B$2:B$24) -> COM | C6: =_xlfn.XLOOKUP(A6,FACULTY_DATA!$B$2:$B$9,FACULTY_DATA!$D$2:$D$9) -> Faculty of Commerce | D6: DEP-COM-COM | E6: =_xlfn.XLOOKUP(D6,DEPARTMENT_DATA!$C$2:$C$24,DEPARTMENT_DATA!$D$2:$D$24) -> COM | F6: Department of Commerce | G6: ="PRG-"&B6&"-"&E6&"-"&H6 -> PRG-COM-COM-BCOM-GF | H6: BCOM-GF | I6: Bachelor of Commerce in Global Finance
A7: =_xlfn.XLOOKUP(D7,DEPARTMENT_DATA!C$2:C$24,DEPARTMENT_DATA!A$2:A$24) -> FAC-ENG | B7: =_xlfn.XLOOKUP(E7,DEPARTMENT_DATA!D$2:D$24,DEPARTMENT_DATA!B$2:B$24) -> ENG | C7: =_xlfn.XLOOKUP(A7,FACULTY_DATA!$B$2:$B$9,FACULTY_DATA!$D$2:$D$9) -> Faculty of Engineering | D7: DEP-ENG-CSE | E7: =_xlfn.XLOOKUP(D7,DEPARTMENT_DATA!$C$2:$C$24,DEPARTMENT_DATA!$D$2:$D$24) -> CSE | F7: Department of Computer Science Engineering | G7: ="PRG-"&B7&"-"&E7&"-"&H7 -> PRG-ENG-CSE-BTECH-CSE | H7: BTECH-CSE | I7: Bachelor of Technology in Computer Science Engineering
A8: =_xlfn.XLOOKUP(D8,DEPARTMENT_DATA!C$2:C$24,DEPARTMENT_DATA!A$2:A$24) -> FAC-ENG | B8: =_xlfn.XLOOKUP(E8,DEPARTMENT_DATA!D$2:D$24,DEPARTMENT_DATA!B$2:B$24) -> ENG | C8: =_xlfn.XLOOKUP(A8,FACULTY_DATA!$B$2:$B$9,FACULTY_DATA!$D$2:$D$9) -> Faculty of Engineering | D8: DEP-ENG-CSE | E8: =_xlfn.XLOOKUP(D8,DEPARTMENT_DATA!$C$2:$C$24,DEPARTMENT_DATA!$D$2:$D$24) -> CSE | F8: Department of Computer Science Engineering | G8: ="PRG-"&B8&"-"&E8&"-"&H8 -> PRG-ENG-CSE-INT-CSE | H8: INT-CSE | I8: Integrated Bachelor and Master of Technology in Computer Science Engineering
A9: =_xlfn.XLOOKUP(D9,DEPARTMENT_DATA!C$2:C$24,DEPARTMENT_DATA!A$2:A$24) -> FAC-ENG | B9: =_xlfn.XLOOKUP(E9,DEPARTMENT_DATA!D$2:D$24,DEPARTMENT_DATA!B$2:B$24) -> ENG | C9: =_xlfn.XLOOKUP(A9,FACULTY_DATA!$B$2:$B$9,FACULTY_DATA!$D$2:$D$9) -> Faculty of Engineering | D9: DEP-ENG-CSE | E9: =_xlfn.XLOOKUP(D9,DEPARTMENT_DATA!$C$2:$C$24,DEPARTMENT_DATA!$D$2:$D$24) -> CSE | F9: Department of Computer Science Engineering | G9: ="PRG-"&B9&"-"&E9&"-"&H9 -> PRG-ENG-CSE-MTECH-CSE | H9: MTECH-CSE | I9: Master of Technology in Computer Science Engineering
A10: =_xlfn.XLOOKUP(D10,DEPARTMENT_DATA!C$2:C$24,DEPARTMENT_DATA!A$2:A$24) -> FAC-ENG | B10: =_xlfn.XLOOKUP(E10,DEPARTMENT_DATA!D$2:D$24,DEPARTMENT_DATA!B$2:B$24) -> ENG | C10: =_xlfn.XLOOKUP(A10,FACULTY_DATA!$B$2:$B$9,FACULTY_DATA!$D$2:$D$9) -> Faculty of Engineering | D10: DEP-ENG-CSE | E10: =_xlfn.XLOOKUP(D10,DEPARTMENT_DATA!$C$2:$C$24,DEPARTMENT_DATA!$D$2:$D$24) -> CSE | F10: Department of Computer Science Engineering | G10: ="PRG-"&B10&"-"&E10&"-"&H10 -> PRG-ENG-CSE-BCA | H10: BCA | I10: Bachelor of Computer Applications
A11: =_xlfn.XLOOKUP(D11,DEPARTMENT_DATA!C$2:C$24,DEPARTMENT_DATA!A$2:A$24) -> FAC-ENG | B11: =_xlfn.XLOOKUP(E11,DEPARTMENT_DATA!D$2:D$24,DEPARTMENT_DATA!B$2:B$24) -> ENG | C11: =_xlfn.XLOOKUP(A11,FACULTY_DATA!$B$2:$B$9,FACULTY_DATA!$D$2:$D$9) -> Faculty of Engineering | D11: DEP-ENG-CSE | E11: =_xlfn.XLOOKUP(D11,DEPARTMENT_DATA!$C$2:$C$24,DEPARTMENT_DATA!$D$2:$D$24) -> CSE | F11: Department of Computer Science Engineering | G11: ="PRG-"&B11&"-"&E11&"-"&H11 -> PRG-ENG-CSE-MCA | H11: MCA | I11: Master of Computer Applications
A12: =_xlfn.XLOOKUP(D12,DEPARTMENT_DATA!C$2:C$24,DEPARTMENT_DATA!A$2:A$24) -> FAC-ENG | B12: =_xlfn.XLOOKUP(E12,DEPARTMENT_DATA!D$2:D$24,DEPARTMENT_DATA!B$2:B$24) -> ENG | C12: =_xlfn.XLOOKUP(A12,FACULTY_DATA!$B$2:$B$9,FACULTY_DATA!$D$2:$D$9) -> Faculty of Engineering | D12: DEP-ENG-IT | E12: =_xlfn.XLOOKUP(D12,DEPARTMENT_DATA!$C$2:$C$24,DEPARTMENT_DATA!$D$2:$D$24) -> IT | F12: Department of Information Technology | G12: ="PRG-"&B12&"-"&E12&"-"&H12 -> PRG-ENG-IT-BTECH-IT | H12: BTECH-IT | I12: Bachelor of Technology in Information Technology
A13: =_xlfn.XLOOKUP(D13,DEPARTMENT_DATA!C$2:C$24,DEPARTMENT_DATA!A$2:A$24) -> FAC-ENG | B13: =_xlfn.XLOOKUP(E13,DEPARTMENT_DATA!D$2:D$24,DEPARTMENT_DATA!B$2:B$24) -> ENG | C13: =_xlfn.XLOOKUP(A13,FACULTY_DATA!$B$2:$B$9,FACULTY_DATA!$D$2:$D$9) -> Faculty of Engineering | D13: DEP-ENG-IT | E13: =_xlfn.XLOOKUP(D13,DEPARTMENT_DATA!$C$2:$C$24,DEPARTMENT_DATA!$D$2:$D$24) -> IT | F13: Department of Information Technology | G13: ="PRG-"&B13&"-"&E13&"-"&H13 -> PRG-ENG-IT-MTECH-IT | H13: MTECH-IT | I13: Master of Technology in Information Technology
... A45: =_xlfn.XLOOKUP(D45,DEPARTMENT_DATA!C$2:C$24,DEPARTMENT_DATA!A$2:A$24) -> FAC-SCI | B45: =_xlfn.XLOOKUP(E45,DEPARTMENT_DATA!D$2:D$24,DEPARTMENT_DATA!B$2:B$24) -> SCI | C45: =_xlfn.XLOOKUP(A45,FACULTY_DATA!$B$2:$B$9,FACULTY_DATA!$D$2:$D$9) -> Faculty of Science | D45: DEP-SCI-MATH | E45: =_xlfn.XLOOKUP(D45,DEPARTMENT_DATA!$C$2:$C$24,DEPARTMENT_DATA!$D$2:$D$24) -> MATH | F45: Department of Mathematics | G45: ="PRG-"&B45&"-"&E45&"-"&H45 -> PRG-SCI-MATH-MSC-MATH | H45: MSC-MATH | I45: Master of Science in Mathematics
